{
  size: [7, 5, 7],
  entities: [],
  blocks: [
    {
      pos: [0, 0, 0],
      state: 0
    },
    {
      pos: [0, 0, 3],
      state: 0
    },
    {
      pos: [0, 0, 4],
      state: 0
    },
    {
      pos: [1, 0, 1],
      state: 0
    },
    {
      pos: [1, 0, 2],
      state: 0
    },
    {
      pos: [1, 0, 3],
      state: 0
    },
    {
      pos: [1, 0, 4],
      state: 0
    },
    {
      pos: [1, 0, 5],
      state: 0
    },
    {
      pos: [1, 0, 6],
      state: 0
    },
    {
      pos: [2, 0, 0],
      state: 0
    },
    {
      pos: [2, 0, 1],
      state: 0
    },
    {
      pos: [2, 0, 2],
      state: 0
    },
    {
      pos: [2, 0, 3],
      state: 0
    },
    {
      pos: [2, 0, 4],
      state: 1
    },
    {
      pos: [2, 0, 5],
      state: 0
    },
    {
      pos: [2, 0, 6],
      state: 0
    },
    {
      pos: [3, 0, 0],
      state: 0
    },
    {
      pos: [3, 0, 1],
      state: 0
    },
    {
      pos: [3, 0, 2],
      state: 0
    },
    {
      pos: [3, 0, 3],
      state: 1
    },
    {
      pos: [3, 0, 4],
      state: 0
    },
    {
      pos: [3, 0, 5],
      state: 0
    },
    {
      pos: [3, 0, 6],
      state: 0
    },
    {
      pos: [4, 0, 0],
      state: 0
    },
    {
      pos: [4, 0, 1],
      state: 0
    },
    {
      pos: [4, 0, 2],
      state: 0
    },
    {
      pos: [4, 0, 3],
      state: 0
    },
    {
      pos: [4, 0, 4],
      state: 0
    },
    {
      pos: [4, 0, 5],
      state: 0
    },
    {
      pos: [5, 0, 0],
      state: 0
    },
    {
      pos: [5, 0, 1],
      state: 0
    },
    {
      pos: [5, 0, 2],
      state: 0
    },
    {
      pos: [5, 0, 3],
      state: 0
    },
    {
      pos: [5, 0, 4],
      state: 0
    },
    {
      pos: [6, 0, 1],
      state: 0
    },
    {
      pos: [6, 0, 2],
      state: 0
    },
    {
      pos: [0, 1, 3],
      state: 0
    },
    {
      pos: [0, 1, 4],
      state: 0
    },
    {
      pos: [0, 1, 5],
      state: 0
    },
    {
      pos: [1, 1, 2],
      state: 0
    },
    {
      pos: [1, 1, 3],
      state: 0
    },
    {
      pos: [1, 1, 4],
      state: 0
    },
    {
      pos: [1, 1, 5],
      state: 0
    },
    {
      pos: [1, 1, 6],
      state: 0
    },
    {
      pos: [2, 1, 1],
      state: 0
    },
    {
      pos: [2, 1, 2],
      state: 0
    },
    {
      pos: [2, 1, 3],
      state: 0
    },
    {
      pos: [2, 1, 4],
      state: 2
    },
    {
      pos: [2, 1, 5],
      state: 0
    },
    {
      pos: [2, 1, 6],
      state: 0
    },
    {
      pos: [3, 1, 0],
      state: 0
    },
    {
      pos: [3, 1, 1],
      state: 0
    },
    {
      pos: [3, 1, 2],
      state: 0
    },
    {
      pos: [3, 1, 3],
      state: 2
    },
    {
      pos: [3, 1, 4],
      state: 0
    },
    {
      pos: [3, 1, 5],
      state: 0
    },
    {
      pos: [4, 1, 0],
      state: 0
    },
    {
      pos: [4, 1, 1],
      state: 0
    },
    {
      pos: [4, 1, 2],
      state: 0
    },
    {
      pos: [4, 1, 3],
      state: 0
    },
    {
      pos: [4, 1, 4],
      state: 0
    },
    {
      pos: [5, 1, 0],
      state: 0
    },
    {
      pos: [5, 1, 1],
      state: 0
    },
    {
      pos: [5, 1, 2],
      state: 0
    },
    {
      pos: [0, 2, 4],
      state: 0
    },
    {
      pos: [0, 2, 5],
      state: 0
    },
    {
      pos: [0, 2, 6],
      state: 0
    },
    {
      pos: [1, 2, 2],
      state: 0
    },
    {
      pos: [1, 2, 3],
      state: 0
    },
    {
      pos: [1, 2, 4],
      state: 0
    },
    {
      pos: [1, 2, 5],
      state: 0
    },
    {
      pos: [1, 2, 6],
      state: 0
    },
    {
      pos: [2, 2, 2],
      state: 0
    },
    {
      pos: [2, 2, 5],
      state: 0
    },
    {
      pos: [3, 2, 0],
      state: 0
    },
    {
      pos: [3, 2, 1],
      state: 0
    },
    {
      pos: [3, 2, 2],
      state: 0
    },
    {
      pos: [3, 2, 4],
      state: 0
    },
    {
      pos: [3, 2, 5],
      state: 0
    },
    {
      pos: [4, 2, 1],
      state: 0
    },
    {
      pos: [4, 2, 2],
      state: 0
    },
    {
      pos: [4, 2, 3],
      state: 0
    },
    {
      pos: [4, 2, 4],
      state: 0
    },
    {
      pos: [0, 3, 4],
      state: 0
    },
    {
      pos: [0, 3, 5],
      state: 0
    },
    {
      pos: [0, 3, 6],
      state: 0
    },
    {
      pos: [1, 3, 3],
      state: 0
    },
    {
      pos: [1, 3, 5],
      state: 0
    },
    {
      pos: [2, 3, 2],
      state: 0
    },
    {
      pos: [2, 3, 5],
      state: 0
    },
    {
      pos: [3, 3, 1],
      state: 0
    },
    {
      pos: [3, 3, 4],
      state: 0
    },
    {
      pos: [3, 3, 5],
      state: 0
    },
    {
      pos: [4, 3, 1],
      state: 0
    },
    {
      pos: [4, 3, 2],
      state: 0
    },
    {
      pos: [4, 3, 3],
      state: 0
    },
    {
      pos: [0, 4, 4],
      state: 0
    },
    {
      pos: [0, 4, 5],
      state: 0
    },
    {
      pos: [1, 4, 5],
      state: 0
    },
    {
      pos: [2, 4, 5],
      state: 0
    },
    {
      pos: [4, 4, 1],
      state: 0
    },
    {
      pos: [4, 4, 2],
      state: 0
    },
    {
      pos: [2, 2, 3],
      state: 3
    },
    {
      pos: [2, 2, 4],
      state: 3
    },
    {
      pos: [3, 2, 3],
      state: 3
    },
    {
      pos: [1, 3, 4],
      state: 3
    },
    {
      pos: [2, 3, 3],
      state: 3
    },
    {
      pos: [2, 3, 4],
      state: 3
    },
    {
      pos: [3, 3, 2],
      state: 3
    },
    {
      pos: [3, 3, 3],
      state: 3
    }
  ],
  palette: [
    {
      Name: "minecraft:sulfur"
    },
    {
      Name: "minecraft:magma_block"
    },
    {
      Name: "minecraft:potent_sulfur"
    },
    {
      Properties: {
        level: "0"
      },
      Name: "minecraft:water"
    }
  ],
  DataVersion: 4887
}