{
  size: [5, 3, 5],
  entities: [],
  blocks: [
    {
      pos: [0, 0, 0],
      state: 0
    },
    {
      pos: [0, 0, 2],
      state: 0
    },
    {
      pos: [0, 0, 3],
      state: 0
    },
    {
      pos: [1, 0, 1],
      state: 0
    },
    {
      pos: [1, 0, 2],
      state: 0
    },
    {
      pos: [1, 0, 3],
      state: 0
    },
    {
      pos: [1, 0, 4],
      state: 0
    },
    {
      pos: [2, 0, 0],
      state: 0
    },
    {
      pos: [2, 0, 1],
      state: 0
    },
    {
      pos: [2, 0, 2],
      state: 1
    },
    {
      pos: [2, 0, 3],
      state: 0
    },
    {
      pos: [2, 0, 4],
      state: 0
    },
    {
      pos: [3, 0, 1],
      state: 0
    },
    {
      pos: [3, 0, 2],
      state: 0
    },
    {
      pos: [3, 0, 3],
      state: 0
    },
    {
      pos: [3, 0, 4],
      state: 0
    },
    {
      pos: [4, 0, 2],
      state: 0
    },
    {
      pos: [4, 0, 3],
      state: 0
    },
    {
      pos: [0, 1, 2],
      state: 0
    },
    {
      pos: [1, 1, 2],
      state: 0
    },
    {
      pos: [1, 1, 3],
      state: 0
    },
    {
      pos: [2, 1, 1],
      state: 0
    },
    {
      pos: [2, 1, 2],
      state: 2
    },
    {
      pos: [2, 1, 3],
      state: 0
    },
    {
      pos: [2, 1, 4],
      state: 0
    },
    {
      pos: [3, 1, 1],
      state: 0
    },
    {
      pos: [3, 1, 2],
      state: 0
    },
    {
      pos: [3, 1, 3],
      state: 0
    },
    {
      pos: [3, 1, 4],
      state: 0
    },
    {
      pos: [4, 1, 3],
      state: 0
    },
    {
      pos: [1, 2, 2],
      state: 0
    },
    {
      pos: [1, 2, 3],
      state: 0
    },
    {
      pos: [2, 2, 1],
      state: 0
    },
    {
      pos: [2, 2, 4],
      state: 0
    },
    {
      pos: [3, 2, 2],
      state: 0
    },
    {
      pos: [3, 2, 3],
      state: 0
    },
    {
      pos: [3, 2, 4],
      state: 0
    },
    {
      pos: [2, 2, 2],
      state: 3
    },
    {
      pos: [2, 2, 3],
      state: 3
    }
  ],
  palette: [
    {
      Name: "minecraft:sulfur"
    },
    {
      Name: "minecraft:magma_block"
    },
    {
      Name: "minecraft:potent_sulfur"
    },
    {
      Properties: {
        level: "0"
      },
      Name: "minecraft:water"
    }
  ],
  DataVersion: 4886
}